[2023-12-02 13:12:06,455] DEBUG: glasgow.device.hardware: found revC3 device with serial C3-20221212T224105Z
[2023-12-02 13:12:06,460] DEBUG: glasgow.applet.video.scan_gen: claimed pipe P and port(s) A, B
[2023-12-02 13:12:06,460] DEBUG: glasgow.applet.video.scan_gen: adding reset register at address 0x00
[2023-12-02 13:12:06,493] DEBUG: glasgow.target.toolchain: using toolchain 'system' (yosys 0.33.g2584903a060, nextpnr-ice40 0.6.14.g5b958c4d, icepack 0)
[2023-12-02 13:12:06,493] TRACE: glasgow.target.toolchain: tool 'yosys' is invoked as '/opt/homebrew/bin/yosys'
[2023-12-02 13:12:06,493] TRACE: glasgow.target.toolchain: tool 'nextpnr-ice40' is invoked as '/opt/bin/nextpnr-ice40'
[2023-12-02 13:12:06,493] TRACE: glasgow.target.toolchain: tool 'icepack' is invoked as '/opt/homebrew/bin/icepack'
[2023-12-02 13:12:06,493] TRACE: glasgow.target.toolchain: toolchain ID is 401b3dabaef593b7c644355b8c3eac1d
[2023-12-02 13:12:07,589] TRACE: glasgow.target.toolchain: tool ID of 'yosys' is e09eb6d24e46a4344c8f87459e32b458
[2023-12-02 13:12:07,589] TRACE: glasgow.target.toolchain: tool ID of 'nextpnr-ice40' is 0539bd0fffc1ce3b8c284d6bbc6d6799
[2023-12-02 13:12:07,589] TRACE: glasgow.target.toolchain: tool ID of 'icepack' is 648c77954d5dcb8ef240774861fdb170
[2023-12-02 13:12:07,795] TRACE: glasgow.device.hardware: USB: CONTROL IN type=0x40 request=0x18 value=0x0000 index=0x0000 length=16 (submit)
[2023-12-02 13:12:07,796] TRACE: glasgow.device.hardware: USB: CONTROL IN data=<b5dee38c7d69cbefdcc56b3004bc20b9> (completed)
[2023-12-02 13:12:07,798] INFO: g.device.hardware: device already has bitstream ID b5dee38c7d69cbefdcc56b3004bc20b9
[2023-12-02 13:12:07,798] INFO: g.cli: running handler for applet 'scan-gen'
[2023-12-02 13:12:07,798] WARNING: g.cli: applet 'scan-gen' is PREVIEW QUALITY and may CORRUPT DATA
[2023-12-02 13:12:07,798] TRACE: glasgow.device.hardware: USB: CONTROL OUT type=0x40 request=0x14 value=0x0000 index=0x0003 data=<e40c> (submit)
[2023-12-02 13:12:07,799] TRACE: glasgow.device.hardware: USB: CONTROL OUT (completed)
[2023-12-02 13:12:07,799] TRACE: glasgow.device.hardware: USB: CONTROL IN type=0x40 request=0x12 value=0x0000 index=0x0000 length=1 (submit)
[2023-12-02 13:12:07,799] TRACE: glasgow.device.hardware: USB: CONTROL IN data=<02> (completed)
[2023-12-02 13:12:07,799] INFO: g.applet.video.scan_gen: port(s) A, B voltage set to 3.3 V
[2023-12-02 13:12:07,799] TRACE: glasgow.device.hardware: USB: CONTROL OUT type=0x40 request=0x1b value=0x0000 index=0x0001 data=<0000> (submit)
[2023-12-02 13:12:07,800] TRACE: glasgow.device.hardware: USB: CONTROL OUT (completed)
[2023-12-02 13:12:07,800] TRACE: glasgow.device.hardware: USB: CONTROL IN type=0x40 request=0x12 value=0x0000 index=0x0000 length=1 (submit)
[2023-12-02 13:12:07,800] TRACE: glasgow.device.hardware: USB: CONTROL IN data=<02> (completed)
[2023-12-02 13:12:07,800] TRACE: glasgow.device.hardware: USB: CONTROL OUT type=0x40 request=0x1b value=0x0000 index=0x0002 data=<0000> (submit)
[2023-12-02 13:12:07,800] TRACE: glasgow.device.hardware: USB: CONTROL OUT (completed)
[2023-12-02 13:12:07,801] TRACE: glasgow.device.hardware: USB: CONTROL IN type=0x40 request=0x12 value=0x0000 index=0x0000 length=1 (submit)
[2023-12-02 13:12:07,801] TRACE: glasgow.device.hardware: USB: CONTROL IN data=<02> (completed)
[2023-12-02 13:12:07,801] DEBUG: glasgow.applet.video.scan_gen: port(s) A, B pull resistors disabled
[2023-12-02 13:12:07,801] TRACE: glasgow.applet.video.scan_gen: asserting reset
[2023-12-02 13:12:07,801] TRACE: glasgow.device.hardware: register 0 write: 0x01
[2023-12-02 13:12:07,801] TRACE: glasgow.device.hardware: USB: CONTROL OUT type=0x40 request=0x13 value=0x0000 index=0x0000 data=<01> (submit)
[2023-12-02 13:12:07,802] TRACE: glasgow.device.hardware: USB: CONTROL OUT (completed)
[2023-12-02 13:12:07,802] TRACE: glasgow.applet.video.scan_gen: FIFO: synchronizing buffers
[2023-12-02 13:12:07,802] TRACE: glasgow.applet.video.scan_gen: FIFO: pipelining reads
[2023-12-02 13:12:07,802] TRACE: glasgow.device.hardware: USB: BULK EP6 IN length=16384 (submit)
[2023-12-02 13:12:07,802] TRACE: glasgow.device.hardware: USB: BULK EP6 IN length=16384 (submit)
[2023-12-02 13:12:07,802] TRACE: glasgow.device.hardware: USB: BULK EP6 IN length=16384 (submit)
[2023-12-02 13:12:07,802] TRACE: glasgow.device.hardware: USB: BULK EP6 IN length=16384 (submit)
[2023-12-02 13:12:07,802] TRACE: glasgow.device.hardware: USB: BULK EP6 IN length=16384 (submit)
[2023-12-02 13:12:07,802] TRACE: glasgow.device.hardware: USB: BULK EP6 IN length=16384 (submit)
[2023-12-02 13:12:07,802] TRACE: glasgow.device.hardware: USB: BULK EP6 IN length=16384 (submit)
[2023-12-02 13:12:07,803] TRACE: glasgow.device.hardware: USB: BULK EP6 IN length=16384 (submit)
[2023-12-02 13:12:07,803] TRACE: glasgow.device.hardware: USB: BULK EP6 IN length=16384 (submit)
[2023-12-02 13:12:07,803] TRACE: glasgow.device.hardware: USB: BULK EP6 IN length=16384 (submit)
[2023-12-02 13:12:07,803] TRACE: glasgow.device.hardware: USB: BULK EP6 IN length=16384 (submit)
[2023-12-02 13:12:07,803] TRACE: glasgow.device.hardware: USB: BULK EP6 IN length=16384 (submit)
[2023-12-02 13:12:07,803] TRACE: glasgow.device.hardware: USB: BULK EP6 IN length=16384 (submit)
[2023-12-02 13:12:07,803] TRACE: glasgow.device.hardware: USB: BULK EP6 IN length=16384 (submit)
[2023-12-02 13:12:07,803] TRACE: glasgow.device.hardware: USB: BULK EP6 IN length=16384 (submit)
[2023-12-02 13:12:07,803] TRACE: glasgow.device.hardware: USB: BULK EP6 IN length=16384 (submit)
[2023-12-02 13:12:07,803] TRACE: glasgow.applet.video.scan_gen: deasserting reset
[2023-12-02 13:12:07,803] TRACE: glasgow.device.hardware: register 0 write: 0x00
[2023-12-02 13:12:07,803] TRACE: glasgow.device.hardware: USB: CONTROL OUT type=0x40 request=0x13 value=0x0000 index=0x0000 data=<00> (submit)
[2023-12-02 13:12:07,803] TRACE: glasgow.device.hardware: USB: CONTROL OUT (completed)
[2023-12-02 13:12:07,940] DEBUG: asyncio: Using selector: _Selector
[2023-12-02 13:12:10,239] TRACE: glasgow.device.hardware: register 2 write: 0x00
[2023-12-02 13:12:10,239] TRACE: glasgow.device.hardware: USB: CONTROL OUT type=0x40 request=0x13 value=0x0002 index=0x0000 data=<00> (submit)
[2023-12-02 13:12:10,240] TRACE: glasgow.device.hardware: USB: CONTROL OUT (completed)
[2023-12-02 13:12:10,240] TRACE: glasgow.device.hardware: register 3 write: 0x04
[2023-12-02 13:12:10,240] TRACE: glasgow.device.hardware: USB: CONTROL OUT type=0x40 request=0x13 value=0x0003 index=0x0000 data=<04> (submit)
[2023-12-02 13:12:10,241] TRACE: glasgow.device.hardware: USB: CONTROL OUT (completed)
[2023-12-02 13:12:18,438] DEBUG: qasync._unix._Selector: Closing
[2023-12-02 13:12:18,441] TRACE: glasgow.applet.video.scan_gen: FIFO: flush
[2023-12-02 13:12:18,441] TRACE: glasgow.applet.video.scan_gen: FIFO: wait for flush
[2023-12-02 13:12:18,441] TRACE: glasgow.device.hardware: USB: BULK EP6 IN data=<0000> (completed)
[2023-12-02 13:12:18,442] TRACE: glasgow.device.hardware: USB: BULK EP6 IN data=<01000200> (completed)
[2023-12-02 13:12:18,442] TRACE: glasgow.device.hardware: USB: BULK EP6 IN data=<0300> (completed)
[2023-12-02 13:12:18,442] TRACE: glasgow.device.hardware: USB: BULK EP6 IN data=<04000500> (completed)
[2023-12-02 13:12:18,442] TRACE: glasgow.device.hardware: USB: BULK EP6 IN data=<06000700080009000a000b000c000d000e000f0010001100120013001400150016001700180019001a001b001c001d00> (completed)
[2023-12-02 13:12:18,442] TRACE: glasgow.device.hardware: USB: BULK EP6 IN data=<1e001f0020002100220023002400250026002700280029002a002b002c002d002e002f0030003100320033003400350036003700380039003a003b003c003d00... (64 bytes total)> (completed)
[2023-12-02 13:12:18,442] TRACE: glasgow.device.hardware: USB: BULK EP6 IN data=<3e003f0040004100420043004400450046004700480049004a004b004c004d004e004f00500051005200530054005500560057005800> (completed)
[2023-12-02 13:12:18,442] TRACE: glasgow.device.hardware: USB: BULK EP6 IN data=<59005a005b005c005d005e005f0060006100620063006400650066006700680069006a006b006c006d006e006f0070007100720073007400750076007700> (completed)
[2023-12-02 13:12:18,442] TRACE: glasgow.device.hardware: USB: BULK EP6 IN data=<780079007a007b007c007d007e007f0080008100820083008400850086008700880089008a008b008c008d008e008f0090009100920093009400950096009700... (72 bytes total)> (completed)
[2023-12-02 13:12:18,442] TRACE: glasgow.device.hardware: USB: BULK EP6 IN data=<9c009d009e009f00a000a100a200a300a400a500a600a700a800a900aa00ab00ac00ad00ae00af00b000b100b200b300b400b500b600b700b800b900ba00bb00... (70 bytes total)> (completed)
[2023-12-02 13:12:18,442] TRACE: glasgow.device.hardware: USB: BULK EP6 IN data=<bf00c000c100c200c300c400c500c600c700c800c900ca00cb00cc00cd00ce00cf00d000d100d200d300d400d500d600d700d800d900da00db00dc00dd00de00... (68 bytes total)> (completed)
[2023-12-02 13:12:18,442] TRACE: glasgow.device.hardware: USB: BULK EP6 IN data=<e100e200e300e400e500e600e700e800e900ea00eb00ec00ed00ee00ef00f000f100f200f300f400f500f600f700f800f900fa00fb00fc00fd00fe00ff000001... (70 bytes total)> (completed)
[2023-12-02 13:12:18,442] TRACE: glasgow.device.hardware: USB: BULK EP6 IN data=<0401050106010701080109010a010b010c010d010e010f0110011101120113011401150116011701180119011a011b011c011d011e011f012001210122012301... (74 bytes total)> (completed)
[2023-12-02 13:12:18,442] TRACE: glasgow.device.hardware: USB: BULK EP6 IN data=<29012a012b012c012d012e012f0130013101320133013401350136013701380139013a013b013c013d013e013f01400141014201430144014501460147014801... (482 bytes total)> (completed)
[2023-12-02 13:12:18,442] TRACE: glasgow.device.hardware: USB: BULK EP6 IN data=<1a021b02> (completed)
[2023-12-02 13:12:18,442] TRACE: glasgow.device.hardware: USB: BULK EP6 IN data=<1c02> (completed)
[2023-12-02 13:12:18,505] ERROR: asyncio: Task exception was never retrieved
future: <Task finished name='Task-4' coro=<DirectDemultiplexerInterface._in_task() done, defined at /Users/isabelburgos/Scan-Gen-Glasgow-Testing/software/glasgow/access/direct/demultiplexer.py:214> exception=RuntimeError('Event loop is closed')>
Traceback (most recent call last):
  File "/Users/isabelburgos/Scan-Gen-Glasgow-Testing/software/glasgow/access/direct/demultiplexer.py", line 225, in _in_task
    self._in_tasks.submit(self._in_task())
  File "/Users/isabelburgos/Scan-Gen-Glasgow-Testing/software/glasgow/support/task_queue.py", line 34, in submit
    future = asyncio.ensure_future(coro)
             ^^^^^^^^^^^^^^^^^^^^^^^^^^^
  File "/opt/homebrew/Cellar/python@3.11/3.11.5/Frameworks/Python.framework/Versions/3.11/lib/python3.11/asyncio/tasks.py", line 649, in ensure_future
    return _ensure_future(coro_or_future, loop=loop)
           ^^^^^^^^^^^^^^^^^^^^^^^^^^^^^^^^^^^^^^^^^
  File "/opt/homebrew/Cellar/python@3.11/3.11.5/Frameworks/Python.framework/Versions/3.11/lib/python3.11/asyncio/tasks.py", line 670, in _ensure_future
    return loop.create_task(coro_or_future)
           ^^^^^^^^^^^^^^^^^^^^^^^^^^^^^^^^
  File "/opt/homebrew/Cellar/python@3.11/3.11.5/Frameworks/Python.framework/Versions/3.11/lib/python3.11/asyncio/base_events.py", line 434, in create_task
    self._check_closed()
  File "/opt/homebrew/Cellar/python@3.11/3.11.5/Frameworks/Python.framework/Versions/3.11/lib/python3.11/asyncio/base_events.py", line 519, in _check_closed
    raise RuntimeError('Event loop is closed')
RuntimeError: Event loop is closed
[2023-12-02 13:12:18,507] ERROR: asyncio: Task exception was never retrieved
future: <Task finished name='Task-5' coro=<DirectDemultiplexerInterface._in_task() done, defined at /Users/isabelburgos/Scan-Gen-Glasgow-Testing/software/glasgow/access/direct/demultiplexer.py:214> exception=RuntimeError('Event loop is closed')>
Traceback (most recent call last):
  File "/Users/isabelburgos/Scan-Gen-Glasgow-Testing/software/glasgow/access/direct/demultiplexer.py", line 225, in _in_task
    self._in_tasks.submit(self._in_task())
  File "/Users/isabelburgos/Scan-Gen-Glasgow-Testing/software/glasgow/support/task_queue.py", line 34, in submit
    future = asyncio.ensure_future(coro)
             ^^^^^^^^^^^^^^^^^^^^^^^^^^^
  File "/opt/homebrew/Cellar/python@3.11/3.11.5/Frameworks/Python.framework/Versions/3.11/lib/python3.11/asyncio/tasks.py", line 649, in ensure_future
    return _ensure_future(coro_or_future, loop=loop)
           ^^^^^^^^^^^^^^^^^^^^^^^^^^^^^^^^^^^^^^^^^
  File "/opt/homebrew/Cellar/python@3.11/3.11.5/Frameworks/Python.framework/Versions/3.11/lib/python3.11/asyncio/tasks.py", line 670, in _ensure_future
    return loop.create_task(coro_or_future)
           ^^^^^^^^^^^^^^^^^^^^^^^^^^^^^^^^
  File "/opt/homebrew/Cellar/python@3.11/3.11.5/Frameworks/Python.framework/Versions/3.11/lib/python3.11/asyncio/base_events.py", line 434, in create_task
    self._check_closed()
  File "/opt/homebrew/Cellar/python@3.11/3.11.5/Frameworks/Python.framework/Versions/3.11/lib/python3.11/asyncio/base_events.py", line 519, in _check_closed
    raise RuntimeError('Event loop is closed')
RuntimeError: Event loop is closed
[2023-12-02 13:12:18,507] ERROR: asyncio: Task exception was never retrieved
future: <Task finished name='Task-6' coro=<DirectDemultiplexerInterface._in_task() done, defined at /Users/isabelburgos/Scan-Gen-Glasgow-Testing/software/glasgow/access/direct/demultiplexer.py:214> exception=RuntimeError('Event loop is closed')>
Traceback (most recent call last):
  File "/Users/isabelburgos/Scan-Gen-Glasgow-Testing/software/glasgow/access/direct/demultiplexer.py", line 225, in _in_task
    self._in_tasks.submit(self._in_task())
  File "/Users/isabelburgos/Scan-Gen-Glasgow-Testing/software/glasgow/support/task_queue.py", line 34, in submit
    future = asyncio.ensure_future(coro)
             ^^^^^^^^^^^^^^^^^^^^^^^^^^^
  File "/opt/homebrew/Cellar/python@3.11/3.11.5/Frameworks/Python.framework/Versions/3.11/lib/python3.11/asyncio/tasks.py", line 649, in ensure_future
    return _ensure_future(coro_or_future, loop=loop)
           ^^^^^^^^^^^^^^^^^^^^^^^^^^^^^^^^^^^^^^^^^
  File "/opt/homebrew/Cellar/python@3.11/3.11.5/Frameworks/Python.framework/Versions/3.11/lib/python3.11/asyncio/tasks.py", line 670, in _ensure_future
    return loop.create_task(coro_or_future)
           ^^^^^^^^^^^^^^^^^^^^^^^^^^^^^^^^
  File "/opt/homebrew/Cellar/python@3.11/3.11.5/Frameworks/Python.framework/Versions/3.11/lib/python3.11/asyncio/base_events.py", line 434, in create_task
    self._check_closed()
  File "/opt/homebrew/Cellar/python@3.11/3.11.5/Frameworks/Python.framework/Versions/3.11/lib/python3.11/asyncio/base_events.py", line 519, in _check_closed
    raise RuntimeError('Event loop is closed')
RuntimeError: Event loop is closed
[2023-12-02 13:12:18,507] ERROR: asyncio: Task exception was never retrieved
future: <Task finished name='Task-7' coro=<DirectDemultiplexerInterface._in_task() done, defined at /Users/isabelburgos/Scan-Gen-Glasgow-Testing/software/glasgow/access/direct/demultiplexer.py:214> exception=RuntimeError('Event loop is closed')>
Traceback (most recent call last):
  File "/Users/isabelburgos/Scan-Gen-Glasgow-Testing/software/glasgow/access/direct/demultiplexer.py", line 225, in _in_task
    self._in_tasks.submit(self._in_task())
  File "/Users/isabelburgos/Scan-Gen-Glasgow-Testing/software/glasgow/support/task_queue.py", line 34, in submit
    future = asyncio.ensure_future(coro)
             ^^^^^^^^^^^^^^^^^^^^^^^^^^^
  File "/opt/homebrew/Cellar/python@3.11/3.11.5/Frameworks/Python.framework/Versions/3.11/lib/python3.11/asyncio/tasks.py", line 649, in ensure_future
    return _ensure_future(coro_or_future, loop=loop)
           ^^^^^^^^^^^^^^^^^^^^^^^^^^^^^^^^^^^^^^^^^
  File "/opt/homebrew/Cellar/python@3.11/3.11.5/Frameworks/Python.framework/Versions/3.11/lib/python3.11/asyncio/tasks.py", line 670, in _ensure_future
    return loop.create_task(coro_or_future)
           ^^^^^^^^^^^^^^^^^^^^^^^^^^^^^^^^
  File "/opt/homebrew/Cellar/python@3.11/3.11.5/Frameworks/Python.framework/Versions/3.11/lib/python3.11/asyncio/base_events.py", line 434, in create_task
    self._check_closed()
  File "/opt/homebrew/Cellar/python@3.11/3.11.5/Frameworks/Python.framework/Versions/3.11/lib/python3.11/asyncio/base_events.py", line 519, in _check_closed
    raise RuntimeError('Event loop is closed')
RuntimeError: Event loop is closed
[2023-12-02 13:12:18,507] ERROR: asyncio: Task exception was never retrieved
future: <Task finished name='Task-8' coro=<DirectDemultiplexerInterface._in_task() done, defined at /Users/isabelburgos/Scan-Gen-Glasgow-Testing/software/glasgow/access/direct/demultiplexer.py:214> exception=RuntimeError('Event loop is closed')>
Traceback (most recent call last):
  File "/Users/isabelburgos/Scan-Gen-Glasgow-Testing/software/glasgow/access/direct/demultiplexer.py", line 225, in _in_task
    self._in_tasks.submit(self._in_task())
  File "/Users/isabelburgos/Scan-Gen-Glasgow-Testing/software/glasgow/support/task_queue.py", line 34, in submit
    future = asyncio.ensure_future(coro)
             ^^^^^^^^^^^^^^^^^^^^^^^^^^^
  File "/opt/homebrew/Cellar/python@3.11/3.11.5/Frameworks/Python.framework/Versions/3.11/lib/python3.11/asyncio/tasks.py", line 649, in ensure_future
    return _ensure_future(coro_or_future, loop=loop)
           ^^^^^^^^^^^^^^^^^^^^^^^^^^^^^^^^^^^^^^^^^
  File "/opt/homebrew/Cellar/python@3.11/3.11.5/Frameworks/Python.framework/Versions/3.11/lib/python3.11/asyncio/tasks.py", line 670, in _ensure_future
    return loop.create_task(coro_or_future)
           ^^^^^^^^^^^^^^^^^^^^^^^^^^^^^^^^
  File "/opt/homebrew/Cellar/python@3.11/3.11.5/Frameworks/Python.framework/Versions/3.11/lib/python3.11/asyncio/base_events.py", line 434, in create_task
    self._check_closed()
  File "/opt/homebrew/Cellar/python@3.11/3.11.5/Frameworks/Python.framework/Versions/3.11/lib/python3.11/asyncio/base_events.py", line 519, in _check_closed
    raise RuntimeError('Event loop is closed')
RuntimeError: Event loop is closed
[2023-12-02 13:12:18,508] ERROR: asyncio: Task exception was never retrieved
future: <Task finished name='Task-9' coro=<DirectDemultiplexerInterface._in_task() done, defined at /Users/isabelburgos/Scan-Gen-Glasgow-Testing/software/glasgow/access/direct/demultiplexer.py:214> exception=RuntimeError('Event loop is closed')>
Traceback (most recent call last):
  File "/Users/isabelburgos/Scan-Gen-Glasgow-Testing/software/glasgow/access/direct/demultiplexer.py", line 225, in _in_task
    self._in_tasks.submit(self._in_task())
  File "/Users/isabelburgos/Scan-Gen-Glasgow-Testing/software/glasgow/support/task_queue.py", line 34, in submit
    future = asyncio.ensure_future(coro)
             ^^^^^^^^^^^^^^^^^^^^^^^^^^^
  File "/opt/homebrew/Cellar/python@3.11/3.11.5/Frameworks/Python.framework/Versions/3.11/lib/python3.11/asyncio/tasks.py", line 649, in ensure_future
    return _ensure_future(coro_or_future, loop=loop)
           ^^^^^^^^^^^^^^^^^^^^^^^^^^^^^^^^^^^^^^^^^
  File "/opt/homebrew/Cellar/python@3.11/3.11.5/Frameworks/Python.framework/Versions/3.11/lib/python3.11/asyncio/tasks.py", line 670, in _ensure_future
    return loop.create_task(coro_or_future)
           ^^^^^^^^^^^^^^^^^^^^^^^^^^^^^^^^
  File "/opt/homebrew/Cellar/python@3.11/3.11.5/Frameworks/Python.framework/Versions/3.11/lib/python3.11/asyncio/base_events.py", line 434, in create_task
    self._check_closed()
  File "/opt/homebrew/Cellar/python@3.11/3.11.5/Frameworks/Python.framework/Versions/3.11/lib/python3.11/asyncio/base_events.py", line 519, in _check_closed
    raise RuntimeError('Event loop is closed')
RuntimeError: Event loop is closed
[2023-12-02 13:12:18,508] ERROR: asyncio: Task exception was never retrieved
future: <Task finished name='Task-10' coro=<DirectDemultiplexerInterface._in_task() done, defined at /Users/isabelburgos/Scan-Gen-Glasgow-Testing/software/glasgow/access/direct/demultiplexer.py:214> exception=RuntimeError('Event loop is closed')>
Traceback (most recent call last):
  File "/Users/isabelburgos/Scan-Gen-Glasgow-Testing/software/glasgow/access/direct/demultiplexer.py", line 225, in _in_task
    self._in_tasks.submit(self._in_task())
  File "/Users/isabelburgos/Scan-Gen-Glasgow-Testing/software/glasgow/support/task_queue.py", line 34, in submit
    future = asyncio.ensure_future(coro)
             ^^^^^^^^^^^^^^^^^^^^^^^^^^^
  File "/opt/homebrew/Cellar/python@3.11/3.11.5/Frameworks/Python.framework/Versions/3.11/lib/python3.11/asyncio/tasks.py", line 649, in ensure_future
    return _ensure_future(coro_or_future, loop=loop)
           ^^^^^^^^^^^^^^^^^^^^^^^^^^^^^^^^^^^^^^^^^
  File "/opt/homebrew/Cellar/python@3.11/3.11.5/Frameworks/Python.framework/Versions/3.11/lib/python3.11/asyncio/tasks.py", line 670, in _ensure_future
    return loop.create_task(coro_or_future)
           ^^^^^^^^^^^^^^^^^^^^^^^^^^^^^^^^
  File "/opt/homebrew/Cellar/python@3.11/3.11.5/Frameworks/Python.framework/Versions/3.11/lib/python3.11/asyncio/base_events.py", line 434, in create_task
    self._check_closed()
  File "/opt/homebrew/Cellar/python@3.11/3.11.5/Frameworks/Python.framework/Versions/3.11/lib/python3.11/asyncio/base_events.py", line 519, in _check_closed
    raise RuntimeError('Event loop is closed')
RuntimeError: Event loop is closed
[2023-12-02 13:12:18,508] ERROR: asyncio: Task exception was never retrieved
future: <Task finished name='Task-11' coro=<DirectDemultiplexerInterface._in_task() done, defined at /Users/isabelburgos/Scan-Gen-Glasgow-Testing/software/glasgow/access/direct/demultiplexer.py:214> exception=RuntimeError('Event loop is closed')>
Traceback (most recent call last):
  File "/Users/isabelburgos/Scan-Gen-Glasgow-Testing/software/glasgow/access/direct/demultiplexer.py", line 225, in _in_task
    self._in_tasks.submit(self._in_task())
  File "/Users/isabelburgos/Scan-Gen-Glasgow-Testing/software/glasgow/support/task_queue.py", line 34, in submit
    future = asyncio.ensure_future(coro)
             ^^^^^^^^^^^^^^^^^^^^^^^^^^^
  File "/opt/homebrew/Cellar/python@3.11/3.11.5/Frameworks/Python.framework/Versions/3.11/lib/python3.11/asyncio/tasks.py", line 649, in ensure_future
    return _ensure_future(coro_or_future, loop=loop)
           ^^^^^^^^^^^^^^^^^^^^^^^^^^^^^^^^^^^^^^^^^
  File "/opt/homebrew/Cellar/python@3.11/3.11.5/Frameworks/Python.framework/Versions/3.11/lib/python3.11/asyncio/tasks.py", line 670, in _ensure_future
    return loop.create_task(coro_or_future)
           ^^^^^^^^^^^^^^^^^^^^^^^^^^^^^^^^
  File "/opt/homebrew/Cellar/python@3.11/3.11.5/Frameworks/Python.framework/Versions/3.11/lib/python3.11/asyncio/base_events.py", line 434, in create_task
    self._check_closed()
  File "/opt/homebrew/Cellar/python@3.11/3.11.5/Frameworks/Python.framework/Versions/3.11/lib/python3.11/asyncio/base_events.py", line 519, in _check_closed
    raise RuntimeError('Event loop is closed')
RuntimeError: Event loop is closed
[2023-12-02 13:12:18,508] ERROR: asyncio: Task exception was never retrieved
future: <Task finished name='Task-12' coro=<DirectDemultiplexerInterface._in_task() done, defined at /Users/isabelburgos/Scan-Gen-Glasgow-Testing/software/glasgow/access/direct/demultiplexer.py:214> exception=RuntimeError('Event loop is closed')>
Traceback (most recent call last):
  File "/Users/isabelburgos/Scan-Gen-Glasgow-Testing/software/glasgow/access/direct/demultiplexer.py", line 225, in _in_task
    self._in_tasks.submit(self._in_task())
  File "/Users/isabelburgos/Scan-Gen-Glasgow-Testing/software/glasgow/support/task_queue.py", line 34, in submit
    future = asyncio.ensure_future(coro)
             ^^^^^^^^^^^^^^^^^^^^^^^^^^^
  File "/opt/homebrew/Cellar/python@3.11/3.11.5/Frameworks/Python.framework/Versions/3.11/lib/python3.11/asyncio/tasks.py", line 649, in ensure_future
    return _ensure_future(coro_or_future, loop=loop)
           ^^^^^^^^^^^^^^^^^^^^^^^^^^^^^^^^^^^^^^^^^
  File "/opt/homebrew/Cellar/python@3.11/3.11.5/Frameworks/Python.framework/Versions/3.11/lib/python3.11/asyncio/tasks.py", line 670, in _ensure_future
    return loop.create_task(coro_or_future)
           ^^^^^^^^^^^^^^^^^^^^^^^^^^^^^^^^
  File "/opt/homebrew/Cellar/python@3.11/3.11.5/Frameworks/Python.framework/Versions/3.11/lib/python3.11/asyncio/base_events.py", line 434, in create_task
    self._check_closed()
  File "/opt/homebrew/Cellar/python@3.11/3.11.5/Frameworks/Python.framework/Versions/3.11/lib/python3.11/asyncio/base_events.py", line 519, in _check_closed
    raise RuntimeError('Event loop is closed')
RuntimeError: Event loop is closed
[2023-12-02 13:12:18,508] ERROR: asyncio: Task exception was never retrieved
future: <Task finished name='Task-13' coro=<DirectDemultiplexerInterface._in_task() done, defined at /Users/isabelburgos/Scan-Gen-Glasgow-Testing/software/glasgow/access/direct/demultiplexer.py:214> exception=RuntimeError('Event loop is closed')>
Traceback (most recent call last):
  File "/Users/isabelburgos/Scan-Gen-Glasgow-Testing/software/glasgow/access/direct/demultiplexer.py", line 225, in _in_task
    self._in_tasks.submit(self._in_task())
  File "/Users/isabelburgos/Scan-Gen-Glasgow-Testing/software/glasgow/support/task_queue.py", line 34, in submit
    future = asyncio.ensure_future(coro)
             ^^^^^^^^^^^^^^^^^^^^^^^^^^^
  File "/opt/homebrew/Cellar/python@3.11/3.11.5/Frameworks/Python.framework/Versions/3.11/lib/python3.11/asyncio/tasks.py", line 649, in ensure_future
    return _ensure_future(coro_or_future, loop=loop)
           ^^^^^^^^^^^^^^^^^^^^^^^^^^^^^^^^^^^^^^^^^
  File "/opt/homebrew/Cellar/python@3.11/3.11.5/Frameworks/Python.framework/Versions/3.11/lib/python3.11/asyncio/tasks.py", line 670, in _ensure_future
    return loop.create_task(coro_or_future)
           ^^^^^^^^^^^^^^^^^^^^^^^^^^^^^^^^
  File "/opt/homebrew/Cellar/python@3.11/3.11.5/Frameworks/Python.framework/Versions/3.11/lib/python3.11/asyncio/base_events.py", line 434, in create_task
    self._check_closed()
  File "/opt/homebrew/Cellar/python@3.11/3.11.5/Frameworks/Python.framework/Versions/3.11/lib/python3.11/asyncio/base_events.py", line 519, in _check_closed
    raise RuntimeError('Event loop is closed')
RuntimeError: Event loop is closed
[2023-12-02 13:12:18,509] ERROR: asyncio: Task exception was never retrieved
future: <Task finished name='Task-14' coro=<DirectDemultiplexerInterface._in_task() done, defined at /Users/isabelburgos/Scan-Gen-Glasgow-Testing/software/glasgow/access/direct/demultiplexer.py:214> exception=RuntimeError('Event loop is closed')>
Traceback (most recent call last):
  File "/Users/isabelburgos/Scan-Gen-Glasgow-Testing/software/glasgow/access/direct/demultiplexer.py", line 225, in _in_task
    self._in_tasks.submit(self._in_task())
  File "/Users/isabelburgos/Scan-Gen-Glasgow-Testing/software/glasgow/support/task_queue.py", line 34, in submit
    future = asyncio.ensure_future(coro)
             ^^^^^^^^^^^^^^^^^^^^^^^^^^^
  File "/opt/homebrew/Cellar/python@3.11/3.11.5/Frameworks/Python.framework/Versions/3.11/lib/python3.11/asyncio/tasks.py", line 649, in ensure_future
    return _ensure_future(coro_or_future, loop=loop)
           ^^^^^^^^^^^^^^^^^^^^^^^^^^^^^^^^^^^^^^^^^
  File "/opt/homebrew/Cellar/python@3.11/3.11.5/Frameworks/Python.framework/Versions/3.11/lib/python3.11/asyncio/tasks.py", line 670, in _ensure_future
    return loop.create_task(coro_or_future)
           ^^^^^^^^^^^^^^^^^^^^^^^^^^^^^^^^
  File "/opt/homebrew/Cellar/python@3.11/3.11.5/Frameworks/Python.framework/Versions/3.11/lib/python3.11/asyncio/base_events.py", line 434, in create_task
    self._check_closed()
  File "/opt/homebrew/Cellar/python@3.11/3.11.5/Frameworks/Python.framework/Versions/3.11/lib/python3.11/asyncio/base_events.py", line 519, in _check_closed
    raise RuntimeError('Event loop is closed')
RuntimeError: Event loop is closed
[2023-12-02 13:12:18,509] ERROR: asyncio: Task exception was never retrieved
future: <Task finished name='Task-15' coro=<DirectDemultiplexerInterface._in_task() done, defined at /Users/isabelburgos/Scan-Gen-Glasgow-Testing/software/glasgow/access/direct/demultiplexer.py:214> exception=RuntimeError('Event loop is closed')>
Traceback (most recent call last):
  File "/Users/isabelburgos/Scan-Gen-Glasgow-Testing/software/glasgow/access/direct/demultiplexer.py", line 225, in _in_task
    self._in_tasks.submit(self._in_task())
  File "/Users/isabelburgos/Scan-Gen-Glasgow-Testing/software/glasgow/support/task_queue.py", line 34, in submit
    future = asyncio.ensure_future(coro)
             ^^^^^^^^^^^^^^^^^^^^^^^^^^^
  File "/opt/homebrew/Cellar/python@3.11/3.11.5/Frameworks/Python.framework/Versions/3.11/lib/python3.11/asyncio/tasks.py", line 649, in ensure_future
    return _ensure_future(coro_or_future, loop=loop)
           ^^^^^^^^^^^^^^^^^^^^^^^^^^^^^^^^^^^^^^^^^
  File "/opt/homebrew/Cellar/python@3.11/3.11.5/Frameworks/Python.framework/Versions/3.11/lib/python3.11/asyncio/tasks.py", line 670, in _ensure_future
    return loop.create_task(coro_or_future)
           ^^^^^^^^^^^^^^^^^^^^^^^^^^^^^^^^
  File "/opt/homebrew/Cellar/python@3.11/3.11.5/Frameworks/Python.framework/Versions/3.11/lib/python3.11/asyncio/base_events.py", line 434, in create_task
    self._check_closed()
  File "/opt/homebrew/Cellar/python@3.11/3.11.5/Frameworks/Python.framework/Versions/3.11/lib/python3.11/asyncio/base_events.py", line 519, in _check_closed
    raise RuntimeError('Event loop is closed')
RuntimeError: Event loop is closed
[2023-12-02 13:12:18,509] ERROR: asyncio: Task exception was never retrieved
future: <Task finished name='Task-16' coro=<DirectDemultiplexerInterface._in_task() done, defined at /Users/isabelburgos/Scan-Gen-Glasgow-Testing/software/glasgow/access/direct/demultiplexer.py:214> exception=RuntimeError('Event loop is closed')>
Traceback (most recent call last):
  File "/Users/isabelburgos/Scan-Gen-Glasgow-Testing/software/glasgow/access/direct/demultiplexer.py", line 225, in _in_task
    self._in_tasks.submit(self._in_task())
  File "/Users/isabelburgos/Scan-Gen-Glasgow-Testing/software/glasgow/support/task_queue.py", line 34, in submit
    future = asyncio.ensure_future(coro)
             ^^^^^^^^^^^^^^^^^^^^^^^^^^^
  File "/opt/homebrew/Cellar/python@3.11/3.11.5/Frameworks/Python.framework/Versions/3.11/lib/python3.11/asyncio/tasks.py", line 649, in ensure_future
    return _ensure_future(coro_or_future, loop=loop)
           ^^^^^^^^^^^^^^^^^^^^^^^^^^^^^^^^^^^^^^^^^
  File "/opt/homebrew/Cellar/python@3.11/3.11.5/Frameworks/Python.framework/Versions/3.11/lib/python3.11/asyncio/tasks.py", line 670, in _ensure_future
    return loop.create_task(coro_or_future)
           ^^^^^^^^^^^^^^^^^^^^^^^^^^^^^^^^
  File "/opt/homebrew/Cellar/python@3.11/3.11.5/Frameworks/Python.framework/Versions/3.11/lib/python3.11/asyncio/base_events.py", line 434, in create_task
    self._check_closed()
  File "/opt/homebrew/Cellar/python@3.11/3.11.5/Frameworks/Python.framework/Versions/3.11/lib/python3.11/asyncio/base_events.py", line 519, in _check_closed
    raise RuntimeError('Event loop is closed')
RuntimeError: Event loop is closed
[2023-12-02 13:12:18,509] ERROR: asyncio: Task exception was never retrieved
future: <Task finished name='Task-17' coro=<DirectDemultiplexerInterface._in_task() done, defined at /Users/isabelburgos/Scan-Gen-Glasgow-Testing/software/glasgow/access/direct/demultiplexer.py:214> exception=RuntimeError('Event loop is closed')>
Traceback (most recent call last):
  File "/Users/isabelburgos/Scan-Gen-Glasgow-Testing/software/glasgow/access/direct/demultiplexer.py", line 225, in _in_task
    self._in_tasks.submit(self._in_task())
  File "/Users/isabelburgos/Scan-Gen-Glasgow-Testing/software/glasgow/support/task_queue.py", line 34, in submit
    future = asyncio.ensure_future(coro)
             ^^^^^^^^^^^^^^^^^^^^^^^^^^^
  File "/opt/homebrew/Cellar/python@3.11/3.11.5/Frameworks/Python.framework/Versions/3.11/lib/python3.11/asyncio/tasks.py", line 649, in ensure_future
    return _ensure_future(coro_or_future, loop=loop)
           ^^^^^^^^^^^^^^^^^^^^^^^^^^^^^^^^^^^^^^^^^
  File "/opt/homebrew/Cellar/python@3.11/3.11.5/Frameworks/Python.framework/Versions/3.11/lib/python3.11/asyncio/tasks.py", line 670, in _ensure_future
    return loop.create_task(coro_or_future)
           ^^^^^^^^^^^^^^^^^^^^^^^^^^^^^^^^
  File "/opt/homebrew/Cellar/python@3.11/3.11.5/Frameworks/Python.framework/Versions/3.11/lib/python3.11/asyncio/base_events.py", line 434, in create_task
    self._check_closed()
  File "/opt/homebrew/Cellar/python@3.11/3.11.5/Frameworks/Python.framework/Versions/3.11/lib/python3.11/asyncio/base_events.py", line 519, in _check_closed
    raise RuntimeError('Event loop is closed')
RuntimeError: Event loop is closed
[2023-12-02 13:12:18,509] ERROR: asyncio: Task exception was never retrieved
future: <Task finished name='Task-18' coro=<DirectDemultiplexerInterface._in_task() done, defined at /Users/isabelburgos/Scan-Gen-Glasgow-Testing/software/glasgow/access/direct/demultiplexer.py:214> exception=RuntimeError('Event loop is closed')>
Traceback (most recent call last):
  File "/Users/isabelburgos/Scan-Gen-Glasgow-Testing/software/glasgow/access/direct/demultiplexer.py", line 225, in _in_task
    self._in_tasks.submit(self._in_task())
  File "/Users/isabelburgos/Scan-Gen-Glasgow-Testing/software/glasgow/support/task_queue.py", line 34, in submit
    future = asyncio.ensure_future(coro)
             ^^^^^^^^^^^^^^^^^^^^^^^^^^^
  File "/opt/homebrew/Cellar/python@3.11/3.11.5/Frameworks/Python.framework/Versions/3.11/lib/python3.11/asyncio/tasks.py", line 649, in ensure_future
    return _ensure_future(coro_or_future, loop=loop)
           ^^^^^^^^^^^^^^^^^^^^^^^^^^^^^^^^^^^^^^^^^
  File "/opt/homebrew/Cellar/python@3.11/3.11.5/Frameworks/Python.framework/Versions/3.11/lib/python3.11/asyncio/tasks.py", line 670, in _ensure_future
    return loop.create_task(coro_or_future)
           ^^^^^^^^^^^^^^^^^^^^^^^^^^^^^^^^
  File "/opt/homebrew/Cellar/python@3.11/3.11.5/Frameworks/Python.framework/Versions/3.11/lib/python3.11/asyncio/base_events.py", line 434, in create_task
    self._check_closed()
  File "/opt/homebrew/Cellar/python@3.11/3.11.5/Frameworks/Python.framework/Versions/3.11/lib/python3.11/asyncio/base_events.py", line 519, in _check_closed
    raise RuntimeError('Event loop is closed')
RuntimeError: Event loop is closed
[2023-12-02 13:12:18,510] ERROR: asyncio: Task exception was never retrieved
future: <Task finished name='Task-19' coro=<DirectDemultiplexerInterface._in_task() done, defined at /Users/isabelburgos/Scan-Gen-Glasgow-Testing/software/glasgow/access/direct/demultiplexer.py:214> exception=RuntimeError('Event loop is closed')>
Traceback (most recent call last):
  File "/Users/isabelburgos/Scan-Gen-Glasgow-Testing/software/glasgow/access/direct/demultiplexer.py", line 225, in _in_task
    self._in_tasks.submit(self._in_task())
  File "/Users/isabelburgos/Scan-Gen-Glasgow-Testing/software/glasgow/support/task_queue.py", line 34, in submit
    future = asyncio.ensure_future(coro)
             ^^^^^^^^^^^^^^^^^^^^^^^^^^^
  File "/opt/homebrew/Cellar/python@3.11/3.11.5/Frameworks/Python.framework/Versions/3.11/lib/python3.11/asyncio/tasks.py", line 649, in ensure_future
    return _ensure_future(coro_or_future, loop=loop)
           ^^^^^^^^^^^^^^^^^^^^^^^^^^^^^^^^^^^^^^^^^
  File "/opt/homebrew/Cellar/python@3.11/3.11.5/Frameworks/Python.framework/Versions/3.11/lib/python3.11/asyncio/tasks.py", line 670, in _ensure_future
    return loop.create_task(coro_or_future)
           ^^^^^^^^^^^^^^^^^^^^^^^^^^^^^^^^
  File "/opt/homebrew/Cellar/python@3.11/3.11.5/Frameworks/Python.framework/Versions/3.11/lib/python3.11/asyncio/base_events.py", line 434, in create_task
    self._check_closed()
  File "/opt/homebrew/Cellar/python@3.11/3.11.5/Frameworks/Python.framework/Versions/3.11/lib/python3.11/asyncio/base_events.py", line 519, in _check_closed
    raise RuntimeError('Event loop is closed')
RuntimeError: Event loop is closed
